# 第 7 章：错误处理

Rust 对可靠性的承诺延伸到了错误处理。错误是软件开发中不可避免的一部分，Rust 提供了多种处理错误的功能。Rust 将错误分为两大类：**不可恢复的 (unrecoverable)** 和 **可恢复的 (recoverable)** 错误。

*   **不可恢复错误**: 通常指示程序中存在 bug，例如尝试访问数组末尾之后的无效索引。对于这类错误，Rust 使用 `panic!` 宏来立即停止程序。
*   **可恢复错误**: 通常是那些可以被合理预料和处理的情况，例如文件未找到或网络请求失败。对于这类错误，Rust 使用 `Result<T, E>` 枚举来表示操作可能成功 (`Ok(T)`) 或失败 (`Err(E)`)。

## 7.1 不可恢复错误与 `panic!`

当 `panic!` 宏执行时，你的程序会默认执行以下操作：
1.  打印一个包含 panic 消息、发生 panic 的源代码位置（文件名、行号、列号）的失败信息。
2.  开始**栈展开 (unwinding)**：Rust 会回溯调用栈，并为遇到的每个函数的局部变量依次运行其 `drop` 方法，以执行任何必要的清理工作（如释放内存、关闭文件等）。这个过程是为了确保资源被正确释放，但它也可能比较耗时。
3.  在栈展开完成后，当前线程会退出。如果这是主线程，整个程序会退出。

**配置 Panic 行为：展开 (Unwind) vs 终止 (Abort)**

*   **展开 (Unwind)**：是 Rust 的默认 panic 行为。它尝试安全地清理资源。
*   **终止 (Abort)**：另一种选择是让程序在 panic 时立即终止，而不进行栈展开和清理。操作系统会负责回收程序占用的所有内存和资源。
    *   **优点**: 可以显著减小最终生成的可执行文件的大小，因为不需要包含栈展开所需的代码和元数据。
    *   **配置**: 要将 panic 行为从默认的展开切换为终止，可以在 `Cargo.toml` 文件的 `[profile.*]` 部分（例如，通常只为发布构建 `[profile.release]` 配置）添加 `panic = 'abort'`。
        ```toml
        [profile.release]
        panic = "abort"
        ```
    *   **适用场景**: 当程序大小至关重要（如嵌入式系统）或者你确信在 panic 时不需要复杂的清理逻辑（例如，程序状态已严重损坏，无法安全清理）时，可以考虑使用终止行为。

```rust
fn main_panic_example() { // Renamed
    // panic!("程序遇到严重错误，即将崩溃并退出！"); // 这行会立即导致 panic

    let v = vec![1, 2, 3];
    // v[99]; // 尝试访问越界索引，这会 panic
             // panic 信息通常是: thread 'main' panicked at 'index out of bounds: the len is 3 but the index is 99' at src/main.rs:X:Y
    println!("这行代码在 panic 之后不会被执行。");
}
```
通常，你应该在代码中那些表示程序处于一种无法处理的、不一致或无效状态（通常是由于逻辑错误、违反了代码假设或契约）的地方使用 `panic!`。对于库代码，除非遇到严重到无法恢复的内部不一致，否则应避免直接 `panic!`，而是返回 `Result` 让调用者处理。

**`panic!` 的回溯信息 (Backtrace)**

当 `panic!` 发生时，为了帮助调试，你可以获取一个**回溯信息 (backtrace)**，它会显示导致错误的函数调用顺序。
*   **启用回溯**: 在运行程序时设置 `RUST_BACKTRACE` 环境变量。
    *   `RUST_BACKTRACE=1 cargo run`：打印一个简洁的回溯。
    *   `RUST_BACKTRACE=full cargo run`：打印一个更详细的回溯。
*   回溯信息对于定位 panic 的根本原因非常有用，特别是当 panic 发生在深层嵌套的函数调用中时。要看到有意义的回溯（包含符号信息），通常需要在 debug 模式下编译，或者在 release 模式下也保留调试符号。

## 7.2 可恢复错误与 `Result<T, E>`

大多数错误并非严重到需要程序完全停止。有时函数会因为一些可以被轻松理解和响应的原因而失败。例如，如果尝试打开一个文件而操作失败，可能是因为它不存在，或者你没有访问权限。这些情况是可预期的，程序应该能够处理它们。

Rust 使用 `Result<T, E>` 枚举来处理这类可恢复错误。
`Result` 枚举的定义（概念上）如下：
```rust
// enum Result<T, E> { // T 和 E 是泛型类型参数
//     Ok(T),    // 成员 Ok，表示操作成功，并包含成功时产生的值，类型为 T
//     Err(E),   // 成员 Err，表示操作失败，并包含失败时产生的错误，类型为 E
// }
```
`T` 代表成功时 `Ok` 成员里返回值的类型，`E` 代表失败时 `Err` 成员里返回的错误的类型。`Result<T, E>` 本身被包含在预导入 (prelude) 中，可以直接使用。

### 7.2.1 使用 `match` 处理 `Result`

当一个函数返回 `Result` 时，调用者需要检查其结果是 `Ok` 还是 `Err`，并相应地处理。最基本的方式是使用 `match` 表达式。

```rust
use std::fs::File;
use std::io::ErrorKind; // ErrorKind 是一个枚举，表示不同类型的 I/O 错误

fn main_match_result() { // Renamed
    let file_path = "hello.txt";
    let greeting_file_result = File::open(file_path); // File::open 返回 Result<std::fs::File, std::io::Error>

    let greeting_file_handle = match greeting_file_result {
        Ok(file) => {
            println!("文件 '{}' 打开成功！", file_path);
            file // greeting_file_handle 将是 File 类型
        }
        Err(error) => {
            // error 的类型是 std::io::Error
            // 我们可以根据 error.kind() 进一步判断错误的具体类型
            match error.kind() {
                ErrorKind::NotFound => { // 如果文件未找到
                    println!("文件 '{}' 未找到，尝试创建它...", file_path);
                    match File::create(file_path) { // File::create 也返回 Result
                        Ok(fc) => {
                            println!("文件 '{}' 已成功创建！", file_path);
                            fc // 返回新创建的文件句柄
                        }
                        Err(e_create) => {
                            panic!("尝试创建文件 '{}' 失败: {:?}", file_path, e_create);
                        }
                    }
                }
                other_error_kind => { // 其他类型的 I/O 错误
                    panic!("打开文件 '{}' 时遇到问题 (Kind: {:?}): {:?}", file_path, other_error_kind, error);
                }
            }
        }
    };
    // 可以使用 greeting_file_handle (类型是 std::fs::File)
    println!("文件句柄: {:?}", greeting_file_handle);
    // 最好在测试后删除创建的文件
    // std::fs::remove_file(file_path).ok();
}
```
虽然 `match` 非常强大和灵活，但对于简单的错误处理，这种嵌套的 `match` 表达式可能会显得有些冗长。

### 7.2.2 `Result` 的快捷方式：`unwrap` 和 `expect`

`Result<T, E>` 类型有很多辅助方法来简化常见操作。其中 `unwrap` 和 `expect` 用于快速获取 `Ok` 中的值，但在 `Err` 时会 panic。

*   **`unwrap(self) -> T`**:
    *   如果 `Result` 值是 `Ok(value)`，`unwrap` 会返回内部的 `value`。
    *   如果 `Result` 是 `Err(error)`，`unwrap` 会调用 `panic!` 宏，并使用 `Err` 中错误的 `Debug` 信息作为 panic 消息。
    ```rust
    // use std::fs::File;
    // let f = File::open("non_existent.txt").unwrap(); // 如果文件不存在，这行会 panic
    ```
*   **`expect(self, msg: &str) -> T`**:
    *   与 `unwrap` 类似，但允许你自定义 `panic!` 时的错误信息。
    ```rust
    // use std::fs::File;
    // let f = File::open("another_non_existent.txt")
    //     .expect("打开 another_non_existent.txt 失败，请检查文件是否存在！"); // panic 时显示此消息
    ```
**何时使用 `unwrap` 和 `expect`**：
`unwrap` 和 `expect` 在原型设计、示例代码或测试中非常方便，因为它们代码简短。然而，在**生产代码中应谨慎使用**。只有在以下情况使用它们才是合理的：
1.  你通过程序逻辑**绝对确定**某个操作不应该失败（即，`Result` 总是 `Ok`）。如果此时它仍然失败了，那通常表示程序中存在一个更深层次的 bug，此时 panic 可能是合理的。
2.  当 `Err` 状态确实代表一个程序无法恢复的、致命的错误，并且你希望程序立即停止时。
在大多数其他情况下，最好使用 `match`、`if let`、`?` 运算符或其他更健壮的错误处理方法，而不是让程序轻易 panic。

### 7.2.3 传播错误 (Propagating Errors)

当你编写一个函数，其内部实现会调用一些可能会失败的操作时，除了在函数内部处理错误外，你还可以选择将错误**返回给该函数的调用者**，让调用者决定如何处理。这称为**传播错误 (propagating the error)**。

```rust
use std::io::{self, Read}; // io 模块本身和 Read trait
use std::fs::File;

// 这个函数尝试从文件读取用户名。
// 它返回 Result<String, io::Error>：
// - 如果成功，返回 Ok(String)，其中 String 是用户名。
// - 如果失败（例如文件打不开或读取错误），返回 Err(io::Error)，将原始的 io::Error 传播出去。
fn read_username_from_file_long_way() -> Result<String, io::Error> {
    let username_file_result = File::open("username.txt"); // File::open 返回 Result

    let mut username_file = match username_file_result {
        Ok(file_handle) => file_handle,
        Err(e) => return Err(e), // 如果打开文件失败，将错误 e 立即返回给调用者
    };

    let mut username = String::new();
    // username_file.read_to_string(&mut username) 也返回 Result<usize, io::Error>
    // usize 是读取的字节数
    match username_file.read_to_string(&mut username) {
        Ok(_) => Ok(username), // 如果读取成功，返回包含文件内容的 Ok(String)
        Err(e) => Err(e),      // 如果读取失败，将错误 e 返回给调用者
    }
}

fn main_propagate_error() { // Renamed
    // std::fs::write("username.txt", "AliceFromTest").expect("Failed to write test file");
    match read_username_from_file_long_way() {
        Ok(username) => println!("从文件读取的用户名 (long way): {}", username),
        Err(e) => println!("读取用户名失败 (long way): {:?}", e),
    }
    // std::fs::remove_file("username.txt").ok();
}
```
这种模式（如果操作失败则提前返回 `Err`）非常常见。

### 7.2.4 `?` 运算符：传播错误的快捷方式

为了简化错误传播的常见模式，Rust 提供了 **`?` 运算符**。
当你在一个返回 `Result<T, E>` 的表达式后面使用 `?` 时：
*   如果该 `Result` 的值是 `Ok(value)`，`?` 运算符会从 `Ok` 中取出内部的 `value`，并且整个 `?` 表达式的值就是这个 `value`。程序会继续正常执行。
*   如果该 `Result` 的值是 `Err(error_value)`，`?` 运算符会导致当前的整个函数**立即返回**，并将这个 `Err(error_value)` 作为当前函数的返回值。

**重要**: `?` 运算符**只能用于签名返回 `Result<T, E>`（或 `Option<T>`，或其他实现了 `std::ops::Try` trait 的类型）的函数中**。返回的 `Err` 类型必须与当前函数签名中声明的错误类型 `E` 兼容（通常通过 `From` trait 实现自动转换）。

```rust
// use std::io::{self, Read}; // Already imported
// use std::fs::File;         // Already imported

// 使用 ? 运算符重写 read_username_from_file
fn read_username_from_file_short_way() -> Result<String, io::Error> {
    let mut username_file = File::open("username.txt")?; // 如果 File::open 返回 Err(e)，此函数立即返回 Err(e)
                                                       // 否则，username_file 会得到 Ok 中的 File 句柄
    let mut username = String::new();
    username_file.read_to_string(&mut username)?;   // 如果 read_to_string 返回 Err(e)，此函数立即返回 Err(e)
                                                    // 否则，username 会包含文件内容
    Ok(username) // 如果所有操作都成功，返回 Ok(username)
}

// 还可以通过链式调用使代码更短
fn read_username_from_file_even_shorter() -> Result<String, io::Error> {
    let mut username = String::new();
    File::open("username.txt")?.read_to_string(&mut username)?; // 链式调用 ?
    Ok(username)
}

// 实际上，标准库提供了更简洁的方式来完成这个特定任务：
// use std::fs;
// fn read_username_from_file_idiomatic() -> Result<String, io::Error> {
//     fs::read_to_string("username.txt") // 这个函数内部已经处理了打开和读取
// }

fn main_question_mark_operator() { // Renamed
    // std::fs::write("username.txt", "BobFromTest").expect("Failed to write test file");
    match read_username_from_file_short_way() {
        Ok(username) => println!("(short_way) 用户名: {}", username),
        Err(e) => println!("(short_way) 错误: {:?}", e),
    }
    match read_username_from_file_even_shorter() {
        Ok(username) => println!("(even_shorter) 用户名: {}", username),
        Err(e) => println!("(even_shorter) 错误: {:?}", e),
    }
    // std::fs::remove_file("username.txt").ok();
}
```
`?` 运算符极大地简化了错误传播的代码，使其更易读、更不易出错。
当 `?` 运算符用于传播一个错误 `E1`，而当前函数的返回类型是 `Result<_, E2>` 时，`?` 会尝试使用 `From` trait 将 `E1` 转换为 `E2` (即调用 `E2::from(E1)` 或 `E1.into()`)。如果 `E2` 实现了 `From<E1>`，转换会自动发生。这使得 `?` 可以优雅地处理和传播来自不同来源的、但可以统一到一个共同错误类型的多种错误。

**`?` 运算符与 `Option<T>`**

`?` 运算符也可以用于 `Option<T>` 类型的值。
*   如果 `Option` 是 `Some(value)`，`?` 表达式的值是 `value`。
*   如果是 `None`，`?` 会使当前函数立即返回 `None`。
使用 `?` 于 `Option` 的函数，其返回类型也必须是 `Option`。

```rust
fn first_char_of_first_word_option(text: &str) -> Option<char> {
    // text.split_whitespace().next() 返回 Option<&str> (第一个词)
    // .chars().next() 返回 Option<char> (词的第一个字符)
    let first_word: &str = text.split_whitespace().next()?; // 如果没有第一个词 (text 为空或只有空格)，此函数返回 None
    let first_char: char = first_word.chars().next()?;    // 如果第一个词是空字符串，此函数返回 None
    Some(first_char)
}

fn main_option_question_mark() { // Renamed
    let text1 = "hello world";
    let text2 = "  "; // 没有词
    let text3 = "";   // 没有词
    let text4 = " Rust"; // 第一个词是 "Rust"

    println!("First char of '{}': {:?}", text1, first_char_of_first_word_option(text1)); // Some('h')
    println!("First char of '{}': {:?}", text2, first_char_of_first_word_option(text2)); // None
    println!("First char of '{}': {:?}", text3, first_char_of_first_word_option(text3)); // None
    println!("First char of '{}': {:?}", text4, first_char_of_first_word_option(text4)); // Some('R')
}
```

## 7.3 自定义错误类型

虽然 `std::io::Error` 或其他标准库错误类型在很多情况下都适用，但有时你可能想定义自己的错误类型，以便：
*   更精确地表达你的库或应用程序中可能发生的特定错误情况。
*   组合来自不同操作（可能产生不同标准错误类型）的多种错误到一个统一的错误类型中。
*   为错误附加更多的上下文信息。

一个好的自定义错误类型通常应该：
1.  实现 `std::fmt::Debug` trait：以便可以使用 `{:?}` 格式化打印调试信息。通常可以通过 `#[derive(Debug)]` 自动实现。
2.  实现 `std::fmt::Display` trait：以便可以使用 `{}` 格式化打印对用户更友好的错误信息。需要手动实现 `fmt` 方法。
3.  实现 `std::error::Error` trait：这是一个标记 trait，表明该类型是用于错误处理的标准错误类型。它还允许你可选地提供错误的“来源 (source)”（即导致此错误的另一个底层错误），从而形成一个错误链。

```rust
use std::fmt;
// use std::fs::File; // Already imported
// use std::io;       // Already imported
// use std::io::Read; // Already imported

// 1. 定义我们的自定义错误类型 (通常是一个枚举)
#[derive(Debug)] // 自动实现 Debug
enum AppError {
    Io(io::Error), // 可以包含(包装)其他错误类型，如 io::Error
    ParsingError(String), // 自定义的解析错误，包含一条消息
    ConfigNotFound { config_path: String }, // 包含特定上下文的错误
    Timeout,
}

// 2. 为自定义错误类型实现 Display trait (用户友好的输出)
impl fmt::Display for AppError {
    fn fmt(&self, f: &mut fmt::Formatter) -> fmt::Result { // 注意这里是 fmt::Result
        match self {
            AppError::Io(underlying_err) => write!(f, "应用程序 IO 错误: {}", underlying_err),
            AppError::ParsingError(msg) => write!(f, "应用程序解析错误: {}", msg),
            AppError::ConfigNotFound { config_path } => write!(f, "配置文件未找到: {}", config_path),
            AppError::Timeout => write!(f, "操作超时"),
        }
    }
}

// 3. 为自定义错误类型实现 Error trait (标准错误行为)
impl std::error::Error for AppError {
    // source() 方法返回导致此错误的底层错误 (如果存在)
    fn source(&self) -> Option<&(dyn std::error::Error + 'static)> { // dyn Error 是 trait object
        match self {
            AppError::Io(underlying_err) => Some(underlying_err), // 提供底层 io::Error 作为 source
            AppError::ParsingError(_) => None,    // 这些自定义错误没有更底层的 source
            AppError::ConfigNotFound { .. } => None,
            AppError::Timeout => None,
        }
    }
}

// (可选但强烈推荐) 实现 From<OtherError> for AppError，以便 `?` 运算符可以自动转换错误类型。
// 例如，实现从 io::Error 到 AppError::Io 的转换：
impl From<io::Error> for AppError {
    fn from(err: io::Error) -> AppError {
        AppError::Io(err) // 将 io::Error 包装到 AppError::Io 成员中
    }
}
// 也可以为其他可能发生的错误类型实现 From，例如将解析库的错误转换为 AppError::ParsingError。

// 示例函数，返回我们自定义的错误类型 AppError
fn load_and_process_config(path: &str) -> Result<String, AppError> {
    // 尝试打开文件，如果失败，io::Error 会通过 `?` 和 `From<io::Error>` 自动转换为 AppError::Io
    let mut file = File::open(path).map_err(|e| { // 手动 map_err 示例，如果不用 From
        if e.kind() == ErrorKind::NotFound {
            AppError::ConfigNotFound { config_path: path.to_string() }
        } else {
            AppError::Io(e) // 或者直接用 e.into() 如果 From<io::Error> 已实现
        }
    })?;
    // 上面的 map_err 可以简化为：
    // let mut file = File::open(path)?; // 如果 From<io::Error> for AppError 已实现

    let mut contents = String::new();
    file.read_to_string(&mut contents)?; // io::Error -> AppError::Io via From

    if contents.trim().is_empty() {
        return Err(AppError::ParsingError("配置文件内容为空".to_string()));
    }

    // 假设这里有一些解析逻辑...
    // if解析失败 { return Err(AppError::ParsingError("无效的配置格式".to_string())); }

    Ok(format!("成功处理配置: {}", contents.trim()))
}

fn main_custom_error_example() { // Renamed
    // std::fs::write("config.toml", "key=value").expect("Failed to write test config");
    // std::fs::write("empty_config.toml", "").expect("Failed to write empty config");

    println!("尝试加载 'config.toml':");
    match load_and_process_config("config.toml") {
        Ok(data) => println!("  {}", data),
        Err(e) => {
            eprintln!("  错误: {}", e); // 使用 Display trait
            if let Some(source) = e.source() {
                eprintln!("    Caused by: {}", source);
            }
        }
    }

    println!("\n尝试加载 'empty_config.toml':");
    match load_and_process_config("empty_config.toml") {
        Ok(data) => println!("  {}", data),
        Err(e) => eprintln!("  错误: {}", e),
    }

    println!("\n尝试加载 'nonexistent_config.toml':");
    match load_and_process_config("nonexistent_config.toml") {
        Ok(data) => println!("  {}", data),
        Err(e) => {
            eprintln!("  错误: {}", e); // AppError::ConfigNotFound 或 AppError::Io
            if let Some(source) = e.source() { // 如果是 AppError::Io，这里会打印底层的 io::Error
                eprintln!("    Caused by: {}", source);
            }
        }
    }
    // std::fs::remove_file("config.toml").ok();
    // std::fs::remove_file("empty_config.toml").ok();
}
```
创建自定义错误类型可以使你的库或应用程序的错误处理更加清晰、具体和模块化。
一些流行的错误处理辅助库如 `thiserror` (用于定义自定义错误类型) 和 `anyhow` (用于应用程序级别的通用错误处理，提供带上下文的 `Error` 类型) 可以进一步简化自定义错误类型的创建和错误管理。

## 7.4 何时使用 `panic!` vs `Result`

决定何时使用 `panic!` 何时使用 `Result` 可能不总是那么清晰，但以下是一些指导原则：

*   **使用 `panic!` 的情况 (通常表示程序缺陷或不可恢复状态)**：
    *   **程序 Bug**: 当代码遇到某种**不应该发生**的状态，并且无法从中安全恢复时。这通常表明程序逻辑中存在一个缺陷（例如，违反了不变量、错误的算法实现、无效的内部状态）。此时，继续执行可能导致更严重的问题或数据损坏，因此 panic 以快速失败可能是合适的。
    *   **示例、原型和测试**: 在编写示例代码、快速原型或测试时，如果某个操作失败意味着示例的前提不成立或测试应该失败，使用 `unwrap()` 或 `expect()` (它们在错误时会 panic) 是可以接受的，因为它们代码简洁。
    *   **无法修复的外部状态**: 当你调用的外部代码（例如，不受你控制的库或系统调用）返回一个无效状态，而你的代码无法修复或安全地处理这个无效状态时。
    *   **违反代码契约**: 当一个函数接收到的参数违反了其文档中明确说明的前提条件（契约），并且这种前提条件在类型系统中无法静态保证时。例如，一个函数期望输入一个非空列表，但收到了一个空列表。
    *   **总结**: `panic!` 适用于那些开发者认为“这种情况绝对不应该发生，如果发生了，我宁愿程序崩溃也不要继续运行并可能造成更大破坏”的场景。

*   **使用 `Result<T, E>` 的情况 (用于可预期的、可处理的失败)**：
    *   **预期的失败**: 当错误是**预期可能发生**的，并且调用者应该能够（或被期望）决定如何响应时。例如，文件未找到、网络连接超时、用户输入格式无效、权限不足等。这些不是程序本身的 bug，而是与外部环境或输入相关的正常操作可能遇到的问题。
    *   **给调用者选择**: 当你希望给函数的调用者一个机会来恢复错误、重试操作、记录错误并继续，或者以特定方式处理失败时。
    *   **库的公共 API**: 作为库 (library crate) 的公共 API，通常应该返回 `Result<T, E>` 来报告可恢复的错误，而不是直接 `panic!`。这允许库的使用者根据他们自己应用程序的需求来决定如何处理这些错误。直接 panic 的库通常不那么友好和健壮。
    *   **总结**: `Result` 适用于那些“这可能会失败，但失败是操作的一种已知可能性，调用者应该知道如何应对”的场景。

**一个简单的判断方法**：问自己，“如果这个操作失败了，调用我的代码的那部分代码是否能够合理地做些什么来应对？”如果答案是肯定的，那么返回 `Result`。如果答案是否定的（例如，失败意味着整个程序的状态已经损坏到无法信任的程度），那么 `panic!` 可能更合适。

## 7.5 常见陷阱 (本章相关)

1.  **过度使用 `unwrap()` 或 `expect()` 导致意外 Panic**：
    *   **陷阱**: 在生产代码中不加区分地、或在没有充分理由确信操作不会失败的情况下使用 `unwrap()` 或 `expect()`。当 `Result` 或 `Option` 实际为 `Err`/`None` 时，这会导致程序 panic，可能隐藏了本应被用户或系统优雅处理的错误。
    *   **避免**: 养成优先使用 `match`、`if let`、`?` 运算符或 `Result`/`Option` 的组合子方法（如 `unwrap_or_default()`, `unwrap_or_else(|e| ...)`, `map_err(...)`）进行健壮错误处理的习惯。只在以下情况考虑 `unwrap`/`expect`：
        *   你通过程序逻辑**绝对确定**值不可能是 `Err`/`None`（例如，基于之前已验证的不变量）。
        *   在编写示例代码、一次性脚本、或单元测试中，panic 是可接受的快速失败行为。
        *   当 `Err`/`None` 确实代表一个程序无法恢复的、指示内部 bug 的状态时。

2.  **忽略 `Result` 的返回值 (特别是 `#[must_use]` 类型)**：
    *   **陷阱**: 调用一个返回 `Result` 的函数，但完全不使用其返回值（既不 `match`，也不 `unwrap`，也不赋值给变量，也不用 `?`）。许多返回 `Result` 的函数（尤其是那些有副作用的，如文件写入或网络操作）会使用 `#[must_use]` 属性进行标记。如果忽略这些返回值，Rust 编译器通常会发出警告，提示你可能忽略了一个重要的错误。
        ```rust
        // use std::fs::remove_file;
        // remove_file("some_file.txt"); // 返回 Result<(), io::Error>，如果忽略，编译器会警告
        // // 如果 remove_file 失败，错误就被悄悄地忽略了。
        ```
    *   **避免**: 始终检查或处理返回 `Result` 的函数的返回值。即使你认为错误不太可能发生或不重要，至少也应该用 `.ok()` 丢弃错误（如果成功值是 `()`），或者用 `.expect("...")` (如果失败是致命的)，或者记录错误。例如，`remove_file("...").map_err(|e| log::error!("Failed: {}", e)).ok();`。

3.  **`?` 运算符用在不返回 `Result` 或 `Option` 的函数中**：
    *   **陷阱**: `?` 运算符的“提前返回 `Err` 或 `None`”的行为，要求它所在的函数本身的返回类型必须是 `Result<T', E'>`（其中 `E'` 可以从 `?` 所应用的 `Err(E)` 的 `E` 类型转换而来）或 `Option<T'>`。如果在返回其他类型（如 `()`、`String`、`i32` 等）的函数中直接使用 `?`，会导致编译错误。
        ```rust
        // fn my_non_result_func() -> String { // 这个函数不返回 Result
        //     let data = std::fs::read_to_string("file.txt")?; // 编译错误: `?` operator can only be used in a function that returns `Result` or `Option`
        //     data
        // }
        ```
    *   **避免**: 确保使用 `?` 的函数签名返回一个兼容的 `Result` 或 `Option` 类型。如果函数本身不应该传播错误，而应该在内部处理它（例如，提供默认值，或记录错误后继续），则在函数内部使用 `match`、`if let` 或其他组合子方法来处理 `Result`/`Option`，而不是使用 `?`。

4.  **错误类型不匹配与 `?` 运算符的 `From` Trait 要求**：
    *   **陷阱**: 当一个函数返回 `Result<T, MyError>`，而在其内部你调用了另一个函数，该函数返回 `Result<U, OtherError>`，并对结果使用 `?` 时，如果 `MyError` 类型没有实现 `From<OtherError>` trait，那么 `?` 运算符无法自动将 `OtherError` 转换为 `MyError`，会导致编译错误，提示类型不匹配或 `From` trait 未实现。
    *   **避免**:
        *   **实现 `From` Trait**: 为你的自定义错误类型 `MyError` 实现 `impl From<OtherError> for MyError { ... }`。这是最地道的方式，使得 `?` 可以无缝工作。
        *   **使用 `map_err` 手动转换**: 在使用 `?` 之前，使用 `.map_err(MyError::from_other_error_variant)` 或 `.map_err(|e_other| MyError::VariantWrappingOther(e_other))` 来手动将 `OtherError` 转换为 `MyError`。
            ```rust
            // fn process() -> Result<(), MyError> {
            //     let result_from_lib: Result<(), LibError> = some_library_call();
            //     // 假设 MyError 有一个成员可以包装 LibError，并且 MyError 实现了 From<LibError>
            //     result_from_lib?; // OK, ? 会调用 .into()
            //
            //     // 或者，如果 MyError 没有实现 From<LibError>，但可以手动转换：
            //     // result_from_lib.map_err(|lib_e| MyError::from_lib(lib_e))?;
            //     Ok(())
            // }
            ```
        *   **使用通用错误库**: 像 `anyhow` crate 提供的 `anyhow::Error` 类型可以自动包装几乎任何实现了 `std::error::Error` 的错误，简化了多种错误类型的处理和传播。

5.  **在 `main` 函数中直接使用 `?` (Rust 2018 之前，或未使用 `Result` 返回类型时)**：
    *   **陷阱**: 在 Rust 2018 版本之前，`main` 函数不能直接返回 `Result` 类型，因此不能在 `main` 中直接使用 `?` 运算符来传播错误。即使在 Rust 2018 及之后，如果 `main` 函数的签名仍然是 `fn main() { ... }` (隐式返回 `()`)，也不能在其中使用 `?`。
    *   **避免 (Rust 2018 及之后)**：让 `main` 函数返回一个 `Result<(), E>` 类型，其中 `E` 是一个实现了 `std::error::Error` trait 的错误类型（例如，`Box<dyn std::error::Error>` 是一个常见的选择，可以包装任何标准错误）。这样就可以在 `main` 函数体内部自由使用 `?` 运算符了。
        ```rust
        // // Rust 2018 及更高版本
        // use std::error::Error; // 需要引入 Error trait
        // fn main() -> Result<(), Box<dyn Error>> { // main 返回 Result
        //     let content = std::fs::read_to_string("notes.txt")?; // 可以使用 ?
        //     println!("File content: {}", content);
        //     Ok(()) // main 成功完成，返回 Ok(())
        // }
        ```
    *   **避免 (Rust 2015 或 `main` 不返回 `Result`)**: 需要在一个包装函数中执行可能失败的操作并返回 `Result`，然后在 `main` 中 `match` 这个结果并处理错误（例如，打印错误信息并以非零状态码退出 `std::process::exit(1)`)。

## 7.6 常见面试题 (本章相关，已补充和深化)

1.  **Q: Rust 中处理错误的两种主要方式是什么 (`panic!` vs `Result`)？它们各自的核心区别和典型适用场景是什么？**
    *   **A: (详细解释)**
        Rust 将错误分为不可恢复错误和可恢复错误，并提供了不同的处理机制：
        1.  **不可恢复错误 (Unrecoverable Errors) - 使用 `panic!` 宏**:
            *   **核心区别**: `panic!` 用于指示程序遇到了一个它**无法安全或合理地从中恢复**的严重问题，通常是由于程序自身的 bug、违反了不变量或进入了无效状态。当 `panic!` 执行时，程序默认会展开调用栈（清理资源）然后终止当前线程（如果是主线程，则整个程序终止）。
            *   **典型适用场景**:
                *   **程序缺陷 (Bugs)**: 当检测到程序内部逻辑错误，使得程序处于一种不一致或无法继续安全执行的状态时。例如，访问数组越界、除以零（对于整数）、断言失败等，这些通常是编程错误。
                *   **违反不变量或契约**: 当代码依赖的某个基本假设或契约被违反，且无法在类型系统中静态保证时。
                *   **原型和测试**: 在快速原型开发或测试中，可以使用 `unwrap()` 或 `expect()` (它们在错误时会 panic) 来简化代码，表示“如果这里出错了，那就是个 bug，我希望程序立即停止”。
                *   **示例**: `let x = my_vec[100];` (如果 `my_vec` 长度小于100，会 panic)。`assert_eq!(a, b);` (如果 `a != b`，会 panic)。
        2.  **可恢复错误 (Recoverable Errors) - 使用 `Result<T, E>` 枚举**:
            *   **核心区别**: `Result<T, E>` 用于处理那些**预期可能发生**的、并且调用者应该能够（或被期望）以某种方式响应的错误。它表示一个操作要么成功并返回一个 `T` 类型的值 (`Ok(T)`)，要么失败并返回一个 `E` 类型的错误值 (`Err(E)`)。它不直接终止程序。
            *   **典型适用场景**:
                *   **外部交互失败**: 当与外部系统（如文件系统、网络、数据库、用户输入）交互时，失败是常见的可能性。例如：
                    *   `File::open("path")` 可能因文件不存在或权限不足而失败。
                    *   网络请求可能因服务器无响应、连接超时或 DNS 解析失败而失败。
                    *   解析用户输入或外部数据（如 JSON, CSV）可能因格式错误而失败。
                *   **操作的逻辑失败**: 某些操作根据其定义就可能逻辑上失败。例如，尝试从空队列中取元素。
                *   **库 API 设计**: 库的公共 API 在遇到可预期的失败时，应该返回 `Result`，将错误处理的责任交给库的使用者。直接 panic 的库通常不友好。
                *   **示例**: `File::open("notes.txt")` 返回 `Result<File, io::Error>`。`"123a".parse::<i32>()` 返回 `Result<i32, ParseIntError>`。
        *   **选择原则总结**:
            *   如果错误表示一个**编程错误**或**程序无法安全继续**的状态，并且你不期望调用者能够处理它 -> **`panic!`**。
            *   如果错误是一个**可预期的失败**，调用者应该能够对其进行处理（重试、记录、返回不同结果等） -> **`Result<T, E>`**。
            *   “这个错误是否是我代码的调用者应该合理预料并处理的？” 如果是，用 `Result`。如果不是（“这根本不该发生！”），用 `panic!`。

2.  **Q: 解释 `Result<T, E>` 枚举。除了 `match`，还有哪些常用的方法或操作符来处理或传播 `Result`？**
    *   **A: (详细解释)**
        *   **`Result<T, E>` 枚举**:
            是一个标准库枚举，用于表示一个操作可能成功并返回一个 `T` 类型的值，或者失败并返回一个 `E` 类型的错误。其定义如下：
            ```rust
            // enum Result<T, E> {
            //     Ok(T),  // 成功，包含值 T
            //     Err(E), // 失败，包含错误 E
            // }
            ```
        *   **处理或传播 `Result` 的常用方法/操作符 (除了 `match`)**:
            1.  **`?` 运算符 (Error Propagation Shortcut)**:
                *   用在返回 `Result`（或 `Option`）的函数中。
                *   如果 `my_result?` 中的 `my_result` 是 `Ok(value)`，则整个表达式的值是 `value`。
                *   如果 `my_result` 是 `Err(error)`，则 `?` 会使当前函数**立即返回** `Err(error.into())` (错误类型可能会通过 `From` trait 自动转换)。
                *   极大地简化了错误传播链。
                    ```rust
                    // use std::fs;
                    // fn read_file_to_string(path: &str) -> Result<String, std::io::Error> {
                    //     let content = fs::read_to_string(path)?; // 如果失败，io::Error 被返回
                    //     Ok(content)
                    // }
                    ```
            2.  **`unwrap(self) -> T`**:
                *   如果是 `Ok(value)`，返回 `value`。
                *   如果是 `Err(error)`，则 **panic** (使用 `error` 的 `Debug` 信息)。
                *   **应谨慎使用**，主要用于你确信不应失败的情况或快速原型/测试。
            3.  **`expect(self, msg: &str) -> T`**:
                *   类似 `unwrap()`，但在 `Err` 时 panic 并显示自定义的 `msg`。
                *   同样应谨慎使用。
            4.  **`is_ok(&self) -> bool` 和 `is_err(&self) -> bool`**:
                *   检查 `Result` 是 `Ok` 还是 `Err`，返回布尔值。
            5.  **`ok(self) -> Option<T>` 和 `err(self) -> Option<E>`**:
                *   将 `Result<T, E>` 转换为 `Option<T>` (丢弃 `Err` 值) 或 `Option<E>` (丢弃 `Ok` 值)。
            6.  **`map<U, F>(self, op: F) -> Result<U, E> where F: FnOnce(T) -> U`**:
                *   如果 `Result` 是 `Ok(value)`，对 `value` 应用函数 `op` 并返回 `Ok(op(value))`。
                *   如果 `Result` 是 `Err(error)`，则原样返回 `Err(error)`。
                *   用于转换 `Ok` 中的值类型，而不改变 `Err` 类型。
            7.  **`map_err<F, O>(self, op: O) -> Result<T, F> where O: FnOnce(E) -> F`**:
                *   如果 `Result` 是 `Err(error)`，对 `error` 应用函数 `op` 并返回 `Err(op(error))`。
                *   如果 `Result` 是 `Ok(value)`，则原样返回 `Ok(value)`。
                *   用于转换 `Err` 中的错误类型，而不改变 `Ok` 类型。
            8.  **`and_then<U, F>(self, op: F) -> Result<U, E> where F: FnOnce(T) -> Result<U, E>`**:
                *   如果 `Result` 是 `Ok(value)`，对 `value` 应用函数 `op` (该函数本身返回一个 `Result<U, E>`) 并返回其结果。
                *   如果 `Result` 是 `Err(error)`，则原样返回 `Err(error)`。
                *   用于链式操作，当后续操作也可能失败并返回 `Result` 时。也称为 `flatMap`。
            9.  **`or_else<F, O>(self, op: O) -> Result<T, F> where O: FnOnce(E) -> Result<T, F>`**:
                *   如果 `Result` 是 `Ok(value)`，原样返回 `Ok(value)`。
                *   如果 `Result` 是 `Err(error)`，对 `error` 应用函数 `op` (该函数本身返回一个 `Result<T, F>`) 并返回其结果。
                *   用于在第一个操作失败时尝试另一个可能成功的操作。
            10. **`unwrap_or(self, default: T) -> T`**:
                *   如果是 `Ok(value)`，返回 `value`。
                *   如果是 `Err(_)`，返回提供的 `default` 值。
            11. **`unwrap_or_else<F>(self, op: F) -> T where F: FnOnce(E) -> T`**:
                *   如果是 `Ok(value)`，返回 `value`。
                *   如果是 `Err(error)`，调用闭包 `op` (传入 `error`) 并返回其结果。
        这些方法 (组合子) 提供了强大而灵活的方式来处理 `Result`，通常比复杂的 `match` 嵌套更简洁和易读。

3.  **Q: `?` 运算符在错误传播中的作用是什么？它对函数签名和错误类型有什么要求？**
    *   **A: (详细解释)**
        *   **作用**: `?` 运算符是 Rust 中用于**简化错误传播**的语法糖。当它被应用于一个返回 `Result<T, E>` (或 `Option<T>`) 的表达式时，它会自动处理可能的错误情况：
            *   如果表达式的结果是 `Ok(value)` (或 `Some(value)` for `Option`)，`?` 会从 `Ok` (或 `Some`) 中**提取出内部的 `value`**，并且整个 `?` 表达式的值就是这个 `value`。程序会继续正常执行。
            *   如果表达式的结果是 `Err(error_value)` (或 `None` for `Option`)，`?` 会导致当前的整个函数**立即返回**，并将这个 `Err(error_value)` (或 `None`) 作为当前函数的返回值。
        *   **对函数签名的要求**:
            `?` 运算符**只能用在签名返回 `Result<T', E'>` 或 `Option<T'>`** (或其他实现了内部 `Try` trait 的类型) 的函数中。
            *   如果 `?` 应用于 `Result<_, E>`，则当前函数必须返回 `Result<_, E'>`，其中 `E'` 可以从 `E` 转换而来。
            *   如果 `?` 应用于 `Option<_>`，则当前函数必须返回 `Option<_>`。
            你不能在一个返回普通类型（如 `String` 或 `i32`）或 `()` 的函数中直接使用 `?`。
        *   **对错误类型的要求 (当用于 `Result`)**:
            当 `?` 运算符用于传播一个 `Result<_, E1>` 中的错误 `E1` 时，如果当前函数的返回类型是 `Result<_, E2>`，那么错误类型 `E1` **必须能够通过 `std::convert::From` trait 转换为 `E2`**。也就是说，`E2` 必须实现 `From<E1>` (或者等价地，`E1` 必须实现 `Into<E2>`)。
            *   当 `?` 遇到 `Err(e1_val)` 时，它实际上会执行类似 `return Err(e1_val.into());` 的操作。这个 `.into()` 调用会利用 `From` trait 实现来进行类型转换。
            *   这使得 `?` 非常灵活，可以在一个函数中聚合和传播来自不同库或模块的、具有不同具体错误类型的错误，只要这些错误类型都能被转换（通常是包装）成函数签名中声明的那个统一的错误类型 `E2`。例如，一个函数可能同时调用返回 `std::io::Error` 的操作和返回 `ParseIntError` 的操作，如果函数的返回类型是 `Result<_, MyCustomError>` 并且 `MyCustomError` 实现了 `From<std::io::Error>` 和 `From<ParseIntError>`，那么 `?` 就可以在这两种情况下都正确工作。
        *   **总结**: `?` 运算符是 Rust 中编写健壮且简洁的错误处理代码的关键工具，它通过自动化常见的错误检查和提前返回逻辑，大大减少了样板代码。

4.  **Q: 什么时候应该定义自定义错误类型？一个良好的自定义错误类型通常需要实现哪些核心 trait (`Debug`, `Display`, `Error`)？`thiserror` 和 `anyhow` 这两个流行的 crate 如何帮助错误处理？**
    *   **A: (详细解释)**
        *   **何时定义自定义错误类型**:
            1.  **更具体的错误信息**: 当标准库错误类型（如 `std::io::Error`）不足以精确描述你的库或应用程序中可能发生的特定错误情况时。自定义错误类型可以包含特定于你的领域的上下文信息。
            2.  **统一多种错误来源**: 当你的函数内部调用了多个可能返回不同错误类型的操作，并且你希望将这些不同的底层错误统一包装成一种单一的、对调用者更友好的错误类型时。
            3.  **库 API 设计**: 对于库 (library crate)，提供清晰、具体的自定义错误类型通常是良好 API 设计的一部分，它能帮助库的使用者更好地理解和处理错误。
            4.  **携带额外数据**: 自定义错误类型（通常是枚举或结构体）可以携带任意你需要的数据作为其成员或字段，这些数据可以提供关于错误的更多上下文。
        *   **核心 Trait 实现**: 一个良好的自定义错误类型通常需要实现以下三个核心 trait：
            1.  **`std::fmt::Debug`**:
                *   **目的**: 允许错误类型能够通过 `{:?}` 格式化占位符进行打印，主要用于调试目的。
                *   **实现**: 通常可以通过在类型定义上添加 `#[derive(Debug)]` 属性来自动派生实现。
            2.  **`std::fmt::Display`**:
                *   **目的**: 允许错误类型能够通过 `{}` 格式化占位符进行打印，提供对最终用户更友好的、可读的错误信息。
                *   **实现**: 需要手动实现 `fmt(&self, f: &mut fmt::Formatter) -> fmt::Result` 方法。
            3.  **`std::error::Error`**:
                *   **目的**: 这是 Rust 中所有标准错误类型都应该实现的标记 trait。它表明该类型是用于错误处理的。实现此 trait 还可以：
                    *   可选地通过 `source(&self) -> Option<&(dyn Error + 'static)>` 方法提供导致此错误的**底层错误 (source)**，从而可以形成一个错误链 (error chain or causal chain)。
                    *   使其能够与标准库的其他错误处理机制（如 `Box<dyn Error>`）和第三方错误处理库（如 `anyhow`）更好地集成。
                *   **实现**: 需要手动实现，至少要实现 `Error` trait 本身，并通常也实现 `Display` 和 `Debug`。`source()` 方法是可选的。
            *   **(可选但推荐) `impl From<OtherError> for MyError`**: 为了让 `?` 运算符能够自动将底层错误（如 `io::Error`, `ParseIntError`）转换为你的自定义错误类型，你应该为你的错误类型实现 `From` trait。
        *   **`thiserror` Crate**:
            *   **用途**: `thiserror` 是一个流行的辅助库，用于**简化自定义错误类型的定义 (特别是在库中)**。
            *   **工作方式**: 它提供了一个 `#[derive(Error)]` 过程宏，可以自动为你的自定义错误类型（通常是枚举）派生 `std::error::Error` trait 和 `std::fmt::Display` trait (通过 `#[error("...")]` 属性注解成员) 的实现，以及 `From` trait 的实现 (通过 `#[from]` 属性注解成员的字段)。
            *   **好处**: 大大减少了编写自定义错误类型时所需的样板代码，使得定义结构良好、信息丰富的错误类型更加容易。
                ```rust
                // use thiserror::Error;
                // use std::io;
                // #[derive(Error, Debug)] // thiserror 会自动 derive Error, Debug
                // pub enum DataStoreError {
                //     #[error("数据未找到: {0}")] // 自动实现 Display
                //     NotFound(String),
                //     #[error("IO 错误")] // 自动实现 Display
                //     Io { #[from] source: io::Error }, // 自动实现 From<io::Error> 和 source()
                //     #[error("解析错误: {message}")]
                //     Parse { message: String, #[source] details: Option<Box<dyn std::error::Error + Send + Sync + 'static>> },
                // }
                ```
        *   **`anyhow` Crate**:
            *   **用途**: `anyhow` 主要用于**应用程序级别 (application-level)** 的错误处理，当你不太关心错误的具体类型，而更关心如何方便地**添加上下文信息**、**处理任何实现了 `Error` trait 的错误**，并**轻松地传播它们**时。
            *   **核心类型**: `anyhow::Error` (或其别名 `anyhow::Result<T>` 即 `Result<T, anyhow::Error>`)。`anyhow::Error` 是一个动态的、可以包装任何实现了 `std::error::Error` 的错误类型的“智能指针”错误类型。它可以捕获错误的来源链和回溯信息。
            *   **工作方式**:
                *   `?` 运算符可以无缝地将任何标准错误转换为 `anyhow::Error`。
                *   `.context(message)` 和 `.with_context(|| ...)` 方法可以方便地向错误链中添加描述性的上下文信息。
                *   `anyhow::bail!(message)` 和 `anyhow::ensure!(condition, message)` 等宏可以方便地创建新的 `anyhow::Error`。
            *   **好处**: 极大地简化了应用程序中的错误处理代码，特别是当需要处理来自多个不同库的多种错误类型时。使得错误报告（例如打印给用户或记录到日志）更丰富。
            *   **不适用场景**: 通常不推荐在**库 (library crate)** 的公共 API 中返回 `anyhow::Error`，因为这会隐藏具体的错误类型，使得库的使用者难以根据不同的错误类型进行编程决策。库应该返回更具体的自定义错误类型。

5.  **Q: `main` 函数可以返回 `Result` 吗？如果可以，这样做有什么好处，对错误类型 `E` 有什么要求？**
    *   **A: (详细解释)**
        *   是的，从 Rust 2018 Edition 开始，`main` 函数**可以返回 `Result<T, E>` 类型**。通常，当 `main` 函数用于表示程序是否成功完成时，其成功类型 `T` 是单元类型 `()`，所以签名通常是 `fn main() -> Result<(), E>`。
        *   **好处**:
            1.  **在 `main` 中使用 `?` 运算符**: 这是最主要的好处。如果 `main` 函数返回 `Result`，你就可以在其函数体内部自由地使用 `?` 运算符来传播来自其他函数的错误。如果某个被 `?` 应用的操作返回 `Err(some_error)`，`main` 函数会立即终止，并将 `some_error` (可能经过 `.into()` 转换) 作为整个程序的错误结果。
            2.  **更简洁的错误处理**: 避免了在 `main` 函数中编写大量的 `match` 语句或调用 `.unwrap()`/`.expect()` 来处理可能失败的操作。错误可以自然地向上传播到 `main` 的返回类型。
            3.  **符合 Rust 的错误处理习惯**: 使得 `main` 函数的错误处理方式与其他返回 `Result` 的普通函数更加一致和地道。
            4.  **自动错误报告**: 当 `main` 函数返回 `Err(e)` 时，Rust 的运行时会自动将错误 `e`（通过其 `Debug` 或 `Display` 实现，取决于具体情况）打印到标准错误输出 (stderr)，并且程序会以一个非零的退出状态码结束，向操作系统或调用脚本指示发生了错误。
        *   **对错误类型 `E` 的要求**:
            为了让 `main` 函数能够返回 `Result<(), E>` 并让运行时能够自动打印错误，错误类型 `E` **必须实现 `std::error::Error` trait**。
            *   `std::error::Error` trait 本身要求其实现者也实现 `std::fmt::Debug` 和 `std::fmt::Display`。
            *   一个常见的、通用的选择是使用 `Box<dyn std::error::Error + Send + Sync + 'static>` (通常简写为 `Box<dyn Error>`) 作为 `E` 的类型。`Box<dyn Error>` 是一个 trait 对象，它可以包装任何实现了 `Error` trait（以及 `Send + Sync + 'static`，如果需要跨线程）的错误类型。这使得 `main` 函数可以方便地处理和传播来自项目中任何地方的、符合标准错误模式的各种错误。
                ```rust
                use std::error::Error; // 引入 Error trait
                use std::fs;

                fn main() -> Result<(), Box<dyn Error>> { // main 返回 Result, E 是 Box<dyn Error>
                    let filename = "my_notes.txt";
                    // fs::write(filename, "Important note!")?; // 写入文件，如果失败，? 会传播错误

                    let contents = fs::read_to_string(filename)?; // 读取文件，如果失败，? 会传播错误
                    println!("File contents from '{}':\n{}", filename, contents);

                    // fs::remove_file(filename)?; // 清理，如果失败，? 会传播错误

                    Ok(()) // main 函数成功完成，返回 Ok(())
                }
                ```
            *   如果你有自定义的应用程序级错误类型 `AppError` 并且它实现了 `std::error::Error`，你也可以让 `main` 返回 `Result<(), AppError>`。

6.  **Q: `panic!` 发生时，Rust 程序的“栈展开 (unwinding)”和“立即终止 (abort)”行为有什么区别？如何以及为何要配置这两种行为？**
    *   **A: (详细解释)**
        当 Rust 程序中发生 `panic!` 时，程序会进入一种错误状态。此时，有两种可能的行为来处理这个 panic：
        1.  **栈展开 (Unwinding)**:
            *   **行为**: 这是 Rust 的**默认** panic 行为。当 panic 发生时，当前线程会开始“展开”其调用栈。这意味着程序会从 panic 发生点开始，逆序地遍历调用栈上的每个函数帧。对于每个函数帧中的局部变量，如果该变量的类型实现了 `Drop` trait，其 `drop` 方法会被调用。这个过程一直持续到调用栈的顶部（线程的入口点）。
            *   **目的**: 展开的主要目的是尝试**安全地清理资源**。通过调用 `drop` 方法，可以确保文件句柄被关闭、内存被释放、锁被解锁等，从而避免资源泄漏或使程序处于不一致状态。
            *   **开销**: 栈展开需要额外的工作（遍历栈、调用析构函数），并且需要编译器生成一些元数据来支持展开。这会增加最终二进制文件的大小，并且在 panic 发生时会有一定的运行时开销。
        2.  **立即终止 (Abort)**:
            *   **行为**: 当 panic 发生时，程序**立即终止执行**，不进行任何栈展开或调用 `drop` 方法。所有内存和资源将由操作系统在进程结束时回收。
            *   **优点**:
                *   **更小的二进制文件**: 由于不需要栈展开的元数据和逻辑，生成的二进制文件会更小。
                *   **更快的 Panic 处理**: Panic 发生时，程序立即退出，没有展开的开销。
            *   **缺点**:
                *   **资源可能未被清理**: 任何由程序管理的、依赖 `Drop` 来释放的资源（除了内存，内存会被OS回收）可能不会被正确清理。例如，临时文件可能不会被删除，网络连接可能不会被优雅关闭，外部系统的状态可能不会被更新。
                *   **不运行析构逻辑**: 如果 `drop` 方法中包含了重要的副作用（如写入日志、发送通知），这些将不会执行。
        *   **如何配置**:
            可以在 `Cargo.toml` 文件中为不同的构建配置文件 (profile) 指定 panic 行为。最常见的是为 `release` profile 配置为 `abort`，以获得更小的可执行文件。
            ```toml
            [profile.dev]
            panic = "unwind" # 开发模式默认是 unwind

            [profile.release]
            panic = "abort"  # 发布模式可以配置为 abort
            ```
            也可以通过编译器标志 `-C panic=abort` 或 `-C panic=unwind` 来设置。
        *   **为何要配置 (选择 Unwind 还是 Abort)**:
            *   **选择 `unwind` (默认)**:
                *   当你希望程序在 panic 时尽可能地尝试清理资源，保持一定的状态一致性（尽管 panic 本身通常意味着状态已严重受损）。
                *   当你的代码（或其依赖）依赖 `Drop` 来执行重要的副作用或资源释放时。
                *   当二进制大小不是首要考虑因素时。
            *   **选择 `abort`**:
                *   当**二进制文件大小**是首要考虑因素时，例如在嵌入式系统或 WebAssembly 环境中。
                *   当你确信在 panic 发生时，程序的状态已经无法安全恢复或清理，立即终止是更简单和可预测的选择。
                *   当 panic 发生后，你依赖操作系统来清理所有资源。
                *   **注意**: 如果你的代码需要通过 FFI 与 C 代码（或其他不支持 Rust 式展开的语言）交互，并且 panic 可能跨越 FFI 边界，那么 `abort` 行为通常更安全，因为 Rust 的栈展开可能与外部代码的栈处理不兼容，导致未定义行为。通常，FFI 边界应该使用 `catch_unwind` 来捕获 panic 并将其转换为错误码。

7.  **Q: 除了 `match` 和 `?` 运算符，`Result<T, E>` 还提供了哪些常用的组合子方法 (combinators) 来处理或转换其值？请举例说明 `map`, `map_err`, `and_then`, `or_else` 的用法。**
    *   **A: (详细解释)**
        `Result<T, E>` 类型提供了丰富的组合子方法，这些方法允许以函数式编程的风格链式地处理和转换 `Result` 值，通常比编写复杂的 `match` 表达式更简洁。
        *   **1. `map<U, F>(self, op: F) -> Result<U, E> where F: FnOnce(T) -> U`**:
            *   **作用**: 如果 `Result` 是 `Ok(value)`，则对内部的 `value` 应用函数 `op`，并返回一个新的 `Result::Ok(op(value))`（其中 `op(value)` 的类型是 `U`）。如果 `Result` 是 `Err(error)`，则原样返回 `Err(error)`（错误类型 `E` 不变）。
            *   **用途**: 用于当 `Result` 成功时，对其内部值进行转换或映射，而不改变可能的错误类型。
            *   **示例**:
                ```rust
                // let length_result: Result<usize, String> = Ok("hello".len()); // Ok(5)
                // let length_as_string_result: Result<String, String> = length_result.map(|len_val| len_val.to_string());
                // // length_as_string_result is Ok("5")

                // let err_result: Result<i32, &str> = Err("failed");
                // let mapped_err_result = err_result.map(|x| x * 2); // map 不会作用于 Err
                // // mapped_err_result is Err("failed")
                ```
        *   **2. `map_err<F_err, O>(self, op: O) -> Result<T, F_err> where O: FnOnce(E) -> F_err`**:
            *   **作用**: 如果 `Result` 是 `Err(error)`，则对内部的 `error` 应用函数 `op`，并返回一个新的 `Result::Err(op(error))`（其中 `op(error)` 的类型是新的错误类型 `F_err`）。如果 `Result` 是 `Ok(value)`，则原样返回 `Ok(value)`（成功值 `T` 和其类型不变）。
            *   **用途**: 用于当 `Result` 失败时，对其内部错误值进行转换或映射到另一种错误类型。这在统一不同来源的错误类型时非常有用。
            *   **示例**:
                ```rust
                // use std::num::ParseIntError;
                // fn parse_then_double(s: &str) -> Result<i32, String> { // 返回自定义错误 String
                //     let num_result: Result<i32, ParseIntError> = s.parse();
                //     num_result
                //         .map_err(|parse_err| format!("解析失败: {}", parse_err)) // 将 ParseIntError 转换为 String
                //         .map(|num| num * 2) // 如果成功，则将数字加倍
                // }
                // // parse_then_double("10") -> Ok(20)
                // // parse_then_double("abc") -> Err("解析失败: invalid digit found in string")
                ```
        *   **3. `and_then<U, F>(self, op: F) -> Result<U, E> where F: FnOnce(T) -> Result<U, E>`**:
            *   **作用**: 如果 `Result` 是 `Ok(value)`，则对内部的 `value` 应用函数 `op`。函数 `op` 本身必须返回一个 `Result<U, E>`。`and_then` 会返回 `op(value)` 的结果。如果原始 `Result` 是 `Err(error)`，则原样返回 `Err(error)`。
            *   **用途**: 用于链式执行多个可能失败的操作，其中下一个操作依赖于上一个操作的成功结果。如果任何一步失败，整个链条就会短路并返回第一个遇到的错误。也称为 `flatMap` 或 `bind` (在函数式编程中)。
            *   **示例**:
                ```rust
                // fn sqrt_then_reciprocal(f_str: &str) -> Result<f64, String> {
                //     f_str.parse::<f64>() // 返回 Result<f64, ParseFloatError>
                //         .map_err(|e| e.to_string()) // 转换为 Result<f64, String>
                //         .and_then(|num| { // num 是 f64
                //             if num < 0.0 {
                //                 Err("不能对负数取平方根".to_string())
                //             } else {
                //                 Ok(num.sqrt()) // 返回 Result<f64, String>
                //             }
                //         })
                //         .and_then(|sqrt_num| { // sqrt_num 是 f64
                //             if sqrt_num == 0.0 {
                //                 Err("不能取零的倒数".to_string())
                //             } else {
                //                 Ok(1.0 / sqrt_num) // 返回 Result<f64, String>
                //             }
                //         })
                // }
                // // sqrt_then_reciprocal("4.0") -> Ok(0.5)
                // // sqrt_then_reciprocal("-1.0") -> Err("不能对负数取平方根")
                // // sqrt_then_reciprocal("abc") -> Err("invalid float literal") (来自 parse.map_err)
                ```
        *   **4. `or_else<F_err, O>(self, op: O) -> Result<T, F_err> where O: FnOnce(E) -> Result<T, F_err>`**:
            *   **作用**: 如果 `Result` 是 `Ok(value)`，则原样返回 `Ok(value)`。如果 `Result` 是 `Err(error)`，则对内部的 `error` 应用函数 `op`。函数 `op` 本身必须返回一个 `Result<T, F_err>` (注意，成功类型 `T` 相同，错误类型可能不同 `F_err`)。`or_else` 会返回 `op(error)` 的结果。
            *   **用途**: 用于在第一个操作失败时，尝试执行另一个可能成功（并返回相同成功类型 `T`）的备用操作。如果备用操作也失败，则返回备用操作的错误。
            *   **示例**:
                ```rust
                // use std::fs;
                // use std::io;
                // fn read_primary_or_backup_config(primary_path: &str, backup_path: &str) -> Result<String, io::Error> {
                //     fs::read_to_string(primary_path) // 尝试读取主文件
                //         .or_else(|primary_err| { // 如果主文件读取失败 (primary_err 是 io::Error)
                //             println!("主配置文件读取失败: {}, 尝试备份...", primary_err);
                //             fs::read_to_string(backup_path) // 尝试读取备份文件
                //         })
                // }
                // // let config = read_primary_or_backup_config("config.txt", "config.bak.txt");
                ```
        这些组合子方法使得处理 `Result` 变得非常灵活和富有表现力，有助于编写更简洁、更易读的错误处理代码，同时避免了深层嵌套的 `match` 语句。

第七章 `README.md` 已更新并包含以上面试题及其详细解释。
